<robot name="unicycle">
    <link name="base_link">
        <inertial>
            <origin xyz="0 0 0.5" rpy="0 0 0"/>
            <mass value="1"/>
            <inertia ixx="100" ixy="0" iyy="100" iyz="0" izz="100" />
        </interial>

        <visual>
            <origin xyz="0 0 0" rpy="0 0 0" />
            <geometry>
                <box size="1 1 1" />
            </geometry>
            <material name="Blue">
                <color rgba="0 0 1.0 1.0">
            </material>
        </visual>

        <collision>
            <origin xyz="0 0 0" rpy="0 0 0"/>
            <geometry>
                <box size="1 1 1">
            </geometry>
        </collision>
    </link>
    
    <joint name='base_joint' type="continuous">
        <origin xyz="0 0 0" rpy="0 0 0"/>
        <parent link="base_link"/>
        <child link="stem"/>
        <axis xyz="0 0 1"/>
    </joint>
        
        

